Workbook

Sheet Invoice Log
A1: JOB DETAILS | K1: QUOTE & INVOICE | V1: PAYMENTS RECEIVED | AE1: WHERE IT STANDS | AI1: REFUND - what actually goes back | AO1: FOR THE COLLECTIVE | AQ1: NOTES
A2: Owner | B2: Our Company | C2: Type | D2: INV Number | E2: Client / Booking Name | F2: Event Start | G2: Event End | H2: Invoice Date | I2: New / Repeat | J2: STATUS | K2: Covers | L2: Quote Total (ex VAT) | M2: Cost per Head | N2: VAT Rate | O2: VAT | P2: Total (inc VAT) | Q2: Deposit Req? | R2: Deposit override | S2: Damage Deposit | T2: INVOICE TOTAL (inc deposit) | U2: 1st Invoice (50% + dep) | V2: Payment 1 | W2: Method | X2: Date | Y2: Payment 2 | Z2: Method | AA2: Date | AB2: Payment 3 | AC2: Method | AD2: Date | AE2: TOTAL PAID | AF2: % Paid | AG2: BALANCE OWED | AH2: Days Overdue | AI2: REFUND DUE | AJ2: Account Name | AK2: Sort Code | AL2: Sort Code | AM2: Refund Method | AN2: Refund Paid Date | AO2: DEPOSIT +/- | AP2: FINAL VALUE (ex VAT) | AQ2: Comments | AR2: Event Ref | AS2: Event Mth | AT2: Yr
A3: Danelle | B3: Penni Black | C3: C | D3: 22004198 | E3: JUST | F3: 46037 | H3: 46028 | I3: N | J3: Complete | K3: 120 | L3: 9809.5 | M3: =IF(OR($K3="",$L3=""),"",$L3/$K3) -> 81.745833 | N3: 0.2 | O3: =IF($L3="","",$L3*IF($N3="",Settings!$J$11,$N3)) -> 1961.9 | P3: =IF($L3="","",$L3+$O3) -> 11771.4 | Q3: Yes | S3: =IF($L3="","",IF($Q3<>"Yes",0,IF($R3<>"",$R3,ROUND($L3*Settings!$J$4,2)))) -> 980.95 | T3: =IF($L3="","",$P3+$S3) -> 12752.35 | U3: =IF($L3="","",ROUND($P3/2,2)+$S3) -> 6866.65 | V3: 9468.29 | W3: CC | X3: 46031 | AE3: =IF($L3="","",SUM($V3,$Y3,$AB3)) -> 9468.29 | AF3: =IF(OR($L3="",$T3=0),"",IF(OR($J3="Complete",$J3="Paid in Full"),1,$AE3/$T3)) -> 1 | AG3: =IF($L3="","",IF(OR($J3="Cancelled",$J3="Complete",$J3="Paid in Full"),0,ROUND($T3-$AE3,2))) -> 0 | AH3: =IF(OR($L3="",$H3="",$AG3<=0),"",MAX(0,TODAY()-($H3+Settings!$J$6))) | AI3: 980.95 | AM3: CC | AN3: 46042 | AO3: =IF(OR($L3="",$S3=0,$AI3=""),0,ROUND($S3-$AI3,2)) -> 0 | AP3: =IF($L3="","",ROUND($L3+$AO3,2)) -> 9809.5 | AR3: =IF($L3="","",IF(ISNUMBER($F3),$F3,IF(ISNUMBER($G3),$G3,""))) -> 46037 | AS3: =IF(OR($L3="",$AR3=""),"",DATE(YEAR($AR3),MONTH($AR3),1)) -> 46023 | AT3: =IF($L3="","",IF($AR3<>"",YEAR($AR3),IF(ISNUMBER($H3),YEAR($H3),""))) -> 2026
A4: Danelle | B4: Penni Black | C4: C | D4: 22004199 | E4: London Review of Books | F4: 46038 | H4: 46030 | I4: N | J4: Complete | K4: 60 | L4: 2135.3 | M4: =IF(OR($K4="",$L4=""),"",$L4/$K4) -> 35.588333 | N4: 0.2 | O4: =IF($L4="","",$L4*IF($N4="",Settings!$J$11,$N4)) -> 427.06 | P4: =IF($L4="","",$L4+$O4) -> 2562.36 | Q4: Yes | S4: =IF($L4="","",IF($Q4<>"Yes",0,IF($R4<>"",$R4,ROUND($L4*Settings!$J$4,2)))) -> 213.53 | T4: =IF($L4="","",$P4+$S4) -> 2775.89 | U4: =IF($L4="","",ROUND($P4/2,2)+$S4) -> 1494.71 | V4: 2775.89 | W4: CC | X4: 46031 | AE4: =IF($L4="","",SUM($V4,$Y4,$AB4)) -> 2775.89 | AF4: =IF(OR($L4="",$T4=0),"",IF(OR($J4="Complete",$J4="Paid in Full"),1,$AE4/$T4)) -> 1 | AG4: =IF($L4="","",IF(OR($J4="Cancelled",$J4="Complete",$J4="Paid in Full"),0,ROUND($T4-$AE4,2))) -> 0 | AH4: =IF(OR($L4="",$H4="",$AG4<=0),"",MAX(0,TODAY()-($H4+Settings!$J$6))) | AI4: 213.53 | AM4: CC | AN4: 46042 | AO4: =IF(OR($L4="",$S4=0,$AI4=""),0,ROUND($S4-$AI4,2)) -> 0 | AP4: =IF($L4="","",ROUND($L4+$AO4,2)) -> 2135.3 | AR4: =IF($L4="","",IF(ISNUMBER($F4),$F4,IF(ISNUMBER($G4),$G4,""))) -> 46038 | AS4: =IF(OR($L4="",$AR4=""),"",DATE(YEAR($AR4),MONTH($AR4),1)) -> 46023 | AT4: =IF($L4="","",IF($AR4<>"",YEAR($AR4),IF(ISNUMBER($H4),YEAR($H4),""))) -> 2026
A5: Danelle | B5: Penni Black | C5: C | D5: 22004200 | E5: Berkeley Homes Capital | F5: 46044 | H5: 46030 | I5: R | J5: Complete | K5: 60 | L5: 2106 | M5: =IF(OR($K5="",$L5=""),"",$L5/$K5) -> 35.1 | N5: 0.2 | O5: =IF($L5="","",$L5*IF($N5="",Settings!$J$11,$N5)) -> 421.2 | P5: =IF($L5="","",$L5+$O5) -> 2527.2 | Q5: No | S5: =IF($L5="","",IF($Q5<>"Yes",0,IF($R5<>"",$R5,ROUND($L5*Settings!$J$4,2)))) -> 0 | T5: =IF($L5="","",$P5+$S5) -> 2527.2 | U5: =IF($L5="","",ROUND($P5/2,2)+$S5) -> 1263.6 | V5: 2527.2 | W5: BACS | Y5: 572.4 | Z5: BACS | AA5: 46075 | AE5: =IF($L5="","",SUM($V5,$Y5,$AB5)) -> 3099.6 | AF5: =IF(OR($L5="",$T5=0),"",IF(OR($J5="Complete",$J5="Paid in Full"),1,$AE5/$T5)) -> 1 | AG5: =IF($L5="","",IF(OR($J5="Cancelled",$J5="Complete",$J5="Paid in Full"),0,ROUND($T5-$AE5,2))) -> 0 | AH5: =IF(OR($L5="",$H5="",$AG5<=0),"",MAX(0,TODAY()-($H5+Settings!$J$6))) | AO5: =IF(OR($L5="",$S5=0,$AI5=""),0,ROUND($S5-$AI5,2)) -> 0 | AP5: =IF($L5="","",ROUND($L5+$AO5,2)) -> 2106 | AR5: =IF($L5="","",IF(ISNUMBER($F5),$F5,IF(ISNUMBER($G5),$G5,""))) -> 46044 | AS5: =IF(OR($L5="",$AR5=""),"",DATE(YEAR($AR5),MONTH($AR5),1)) -> 46023 | AT5: =IF($L5="","",IF($AR5<>"",YEAR($AR5),IF(ISNUMBER($H5),YEAR($H5),""))) -> 2026
A6: Danelle | B6: Penni Black | C6: C | D6: 22004201 | E6: Helaba Landesbank Hessen-Thüringen | F6: 46044 | H6: 46030 | I6: R | J6: Complete | K6: 55 | L6: 6799.5 | M6: =IF(OR($K6="",$L6=""),"",$L6/$K6) -> 123.62727 | N6: 0.2 | O6: =IF($L6="","",$L6*IF($N6="",Settings!$J$11,$N6)) -> 1359.9 | P6: =IF($L6="","",$L6+$O6) -> 8159.4 | Q6: Yes | S6: =IF($L6="","",IF($Q6<>"Yes",0,IF($R6<>"",$R6,ROUND($L6*Settings!$J$4,2)))) -> 679.95 | T6: =IF($L6="","",$P6+$S6) -> 8839.35 | U6: =IF($L6="","",ROUND($P6/2,2)+$S6) -> 4759.65 | AE6: =IF($L6="","",SUM($V6,$Y6,$AB6)) -> 0 | AF6: =IF(OR($L6="",$T6=0),"",IF(OR($J6="Complete",$J6="Paid in Full"),1,$AE6/$T6)) -> 1 | AG6: =IF($L6="","",IF(OR($J6="Cancelled",$J6="Complete",$J6="Paid in Full"),0,ROUND($T6-$AE6,2))) -> 0 | AH6: =IF(OR($L6="",$H6="",$AG6<=0),"",MAX(0,TODAY()-($H6+Settings!$J$6))) | AI6: 679.95 | AJ6: Landesbank Hessen-Thuringen Girozentrale | AK6: 5005 0000 | AL6: 096-2211-009 | AM6: BACS | AN6: 46066 | AO6: =IF(OR($L6="",$S6=0,$AI6=""),0,ROUND($S6-$AI6,2)) -> 0 | AP6: =IF($L6="","",ROUND($L6+$AO6,2)) -> 6799.5 | AR6: =IF($L6="","",IF(ISNUMBER($F6),$F6,IF(ISNUMBER($G6),$G6,""))) -> 46044 | AS6: =IF(OR($L6="",$AR6=""),"",DATE(YEAR($AR6),MONTH($AR6),1)) -> 46023 | AT6: =IF($L6="","",IF($AR6<>"",YEAR($AR6),IF(ISNUMBER($H6),YEAR($H6),""))) -> 2026
A7: Danelle | B7: Penni Black | C7: C | D7: 22004202 | E7: AngloGold - Day 1 | F7: 46069 | H7: 46034 | I7: N | J7: Complete | K7: 20 | L7: 3288.5 | M7: =IF(OR($K7="",$L7=""),"",$L7/$K7) -> 164.425 | N7: 0.2 | O7: =IF($L7="","",$L7*IF($N7="",Settings!$J$11,$N7)) -> 657.7 | P7: =IF($L7="","",$L7+$O7) -> 3946.2 | Q7: Yes | S7: =IF($L7="","",IF($Q7<>"Yes",0,IF($R7<>"",$R7,ROUND($L7*Settings!$J$4,2)))) -> 328.85 | T7: =IF($L7="","",$P7+$S7) -> 4275.05 | U7: =IF($L7="","",ROUND($P7/2,2)+$S7) -> 2301.95 | V7: 1080 | W7: CC | X7: 46037 | Y7: 10599.85 | Z7: BACS | AA7: 46065 | AE7: =IF($L7="","",SUM($V7,$Y7,$AB7)) -> 11679.85 | AF7: =IF(OR($L7="",$T7=0),"",IF(OR($J7="Complete",$J7="Paid in Full"),1,$AE7/$T7)) -> 1 | AG7: =IF($L7="","",IF(OR($J7="Cancelled",$J7="Complete",$J7="Paid in Full"),0,ROUND($T7-$AE7,2))) -> 0 | AH7: =IF(OR($L7="",$H7="",$AG7<=0),"",MAX(0,TODAY()-($H7+Settings!$J$6))) | AI7: 328.85 | AJ7: AngloGold Ashanti PLC | AK7: IBAN: GB48CHAS60924280037769 | AL7: 80037769 | AM7: BACS | AN7: 46089 | AO7: =IF(OR($L7="",$S7=0,$AI7=""),0,ROUND($S7-$AI7,2)) -> 0 | AP7: =IF($L7="","",ROUND($L7+$AO7,2)) -> 3288.5 | AR7: =IF($L7="","",IF(ISNUMBER($F7),$F7,IF(ISNUMBER($G7),$G7,""))) -> 46069 | AS7: =IF(OR($L7="",$AR7=""),"",DATE(YEAR($AR7),MONTH($AR7),1)) -> 46054 | AT7: =IF($L7="","",IF($AR7<>"",YEAR($AR7),IF(ISNUMBER($H7),YEAR($H7),""))) -> 2026
A8: Danelle | B8: Penni Black | C8: C | D8: 22004203 | E8: AngloGold - Day 2 | F8: 46070 | H8: 46034 | I8: N | J8: Complete | K8: 20 | L8: 3302 | M8: =IF(OR($K8="",$L8=""),"",$L8/$K8) -> 165.1 | N8: 0.2 | O8: =IF($L8="","",$L8*IF($N8="",Settings!$J$11,$N8)) -> 660.4 | P8: =IF($L8="","",$L8+$O8) -> 3962.4 | Q8: Yes | S8: =IF($L8="","",IF($Q8<>"Yes",0,IF($R8<>"",$R8,ROUND($L8*Settings!$J$4,2)))) -> 330.2 | T8: =IF($L8="","",$P8+$S8) -> 4292.6 | U8: =IF($L8="","",ROUND($P8/2,2)+$S8) -> 2311.4 | AE8: =IF($L8="","",SUM($V8,$Y8,$AB8)) -> 0 | AF8: =IF(OR($L8="",$T8=0),"",IF(OR($J8="Complete",$J8="Paid in Full"),1,$AE8/$T8)) -> 1 | AG8: =IF($L8="","",IF(OR($J8="Cancelled",$J8="Complete",$J8="Paid in Full"),0,ROUND($T8-$AE8,2))) -> 0 | AH8: =IF(OR($L8="",$H8="",$AG8<=0),"",MAX(0,TODAY()-($H8+Settings!$J$6))) | AI8: 330.2 | AO8: =IF(OR($L8="",$S8=0,$AI8=""),0,ROUND($S8-$AI8,2)) -> 0 | AP8: =IF($L8="","",ROUND($L8+$AO8,2)) -> 3302 | AR8: =IF($L8="","",IF(ISNUMBER($F8),$F8,IF(ISNUMBER($G8),$G8,""))) -> 46070 | AS8: =IF(OR($L8="",$AR8=""),"",DATE(YEAR($AR8),MONTH($AR8),1)) -> 46054 | AT8: =IF($L8="","",IF($AR8<>"",YEAR($AR8),IF(ISNUMBER($H8),YEAR($H8),""))) -> 2026
A9: Danelle | B9: Penni Black | C9: C | D9: 22004204 | E9: AngloGold - Day 3 | F9: 46071 | H9: 46034 | I9: N | J9: Complete | K9: 20 | L9: 2394 | M9: =IF(OR($K9="",$L9=""),"",$L9/$K9) -> 119.7 | N9: 0.2 | O9: =IF($L9="","",$L9*IF($N9="",Settings!$J$11,$N9)) -> 478.8 | P9: =IF($L9="","",$L9+$O9) -> 2872.8 | Q9: Yes | S9: =IF($L9="","",IF($Q9<>"Yes",0,IF($R9<>"",$R9,ROUND($L9*Settings!$J$4,2)))) -> 239.4 | T9: =IF($L9="","",$P9+$S9) -> 3112.2 | U9: =IF($L9="","",ROUND($P9/2,2)+$S9) -> 1675.8 | AE9: =IF($L9="","",SUM($V9,$Y9,$AB9)) -> 0 | AF9: =IF(OR($L9="",$T9=0),"",IF(OR($J9="Complete",$J9="Paid in Full"),1,$AE9/$T9)) -> 1 | AG9: =IF($L9="","",IF(OR($J9="Cancelled",$J9="Complete",$J9="Paid in Full"),0,ROUND($T9-$AE9,2))) -> 0 | AH9: =IF(OR($L9="",$H9="",$AG9<=0),"",MAX(0,TODAY()-($H9+Settings!$J$6))) | AI9: 239.4 | AO9: =IF(OR($L9="",$S9=0,$AI9=""),0,ROUND($S9-$AI9,2)) -> 0 | AP9: =IF($L9="","",ROUND($L9+$AO9,2)) -> 2394 | AR9: =IF($L9="","",IF(ISNUMBER($F9),$F9,IF(ISNUMBER($G9),$G9,""))) -> 46071 | AS9: =IF(OR($L9="",$AR9=""),"",DATE(YEAR($AR9),MONTH($AR9),1)) -> 46054 | AT9: =IF($L9="","",IF($AR9<>"",YEAR($AR9),IF(ISNUMBER($H9),YEAR($H9),""))) -> 2026
A10: Danelle | B10: Penni Black | C10: C | D10: 22004205 | E10: Aesop | F10: 46044 | H10: 46036 | I10: N | J10: Complete | K10: 200 | L10: 7765 | M10: =IF(OR($K10="",$L10=""),"",$L10/$K10) -> 38.825 | N10: 0.2 | O10: =IF($L10="","",$L10*IF($N10="",Settings!$J$11,$N10)) -> 1553 | P10: =IF($L10="","",$L10+$O10) -> 9318 | Q10: Yes | S10: =IF($L10="","",IF($Q10<>"Yes",0,IF($R10<>"",$R10,ROUND($L10*Settings!$J$4,2)))) -> 776.5 | T10: =IF($L10="","",$P10+$S10) -> 10094.5 | U10: =IF($L10="","",ROUND($P10/2,2)+$S10) -> 5435.5 | V10: 10094.5 | W10: CC | X10: 46037 | AE10: =IF($L10="","",SUM($V10,$Y10,$AB10)) -> 10094.5 | AF10: =IF(OR($L10="",$T10=0),"",IF(OR($J10="Complete",$J10="Paid in Full"),1,$AE10/$T10)) -> 1 | AG10: =IF($L10="","",IF(OR($J10="Cancelled",$J10="Complete",$J10="Paid in Full"),0,ROUND($T10-$AE10,2))) -> 0 | AH10: =IF(OR($L10="",$H10="",$AG10<=0),"",MAX(0,TODAY()-($H10+Settings!$J$6))) | AI10: 776.5 | AM10: CC | AN10: 46048 | AO10: =IF(OR($L10="",$S10=0,$AI10=""),0,ROUND($S10-$AI10,2)) -> 0 | AP10: =IF($L10="","",ROUND($L10+$AO10,2)) -> 7765 | AR10: =IF($L10="","",IF(ISNUMBER($F10),$F10,IF(ISNUMBER($G10),$G10,""))) -> 46044 | AS10: =IF(OR($L10="",$AR10=""),"",DATE(YEAR($AR10),MONTH($AR10),1)) -> 46023 | AT10: =IF($L10="","",IF($AR10<>"",YEAR($AR10),IF(ISNUMBER($H10),YEAR($H10),""))) -> 2026
A11: Danelle | B11: Penni Black | C11: C | D11: 22004206 | E11: The Payment Association (Emerging Payments Ventures) | F11: 46241 | H11: 46037 | I11: R | J11: Complete | K11: 45 | L11: 5642.45 | M11: =IF(OR($K11="",$L11=""),"",$L11/$K11) -> 125.38778 | N11: 0.2 | O11: =IF($L11="","",$L11*IF($N11="",Settings!$J$11,$N11)) -> 1128.49 | P11: =IF($L11="","",$L11+$O11) -> 6770.94 | Q11: Yes | S11: =IF($L11="","",IF($Q11<>"Yes",0,IF($R11<>"",$R11,ROUND($L11*Settings!$J$4,2)))) -> 564.25 | T11: =IF($L11="","",$P11+$S11) -> 7335.19 | U11: =IF($L11="","",ROUND($P11/2,2)+$S11) -> 3949.72 | V11: 2996.1 | W11: BACS | X11: 46043 | Y11: 4339.08 | Z11: BACS | AA11: 46241 | AE11: =IF($L11="","",SUM($V11,$Y11,$AB11)) -> 7335.18 | AF11: =IF(OR($L11="",$T11=0),"",IF(OR($J11="Complete",$J11="Paid in Full"),1,$AE11/$T11)) -> 1 | AG11: =IF($L11="","",IF(OR($J11="Cancelled",$J11="Complete",$J11="Paid in Full"),0,ROUND($T11-$AE11,2))) -> 0 | AH11: =IF(OR($L11="",$H11="",$AG11<=0),"",MAX(0,TODAY()-($H11+Settings!$J$6))) | AI11: 564.25 | AM11: BACS | AN11: 46275 | AO11: =IF(OR($L11="",$S11=0,$AI11=""),0,ROUND($S11-$AI11,2)) -> 0 | AP11: =IF($L11="","",ROUND($L11+$AO11,2)) -> 5642.45 | AR11: =IF($L11="","",IF(ISNUMBER($F11),$F11,IF(ISNUMBER($G11),$G11,""))) -> 46241 | AS11: =IF(OR($L11="",$AR11=""),"",DATE(YEAR($AR11),MONTH($AR11),1)) -> 46235 | AT11: =IF($L11="","",IF($AR11<>"",YEAR($AR11),IF(ISNUMBER($H11),YEAR($H11),""))) -> 2026
A12: Danelle | B12: Penni Black | C12: C | D12: 22004207 | E12: George Jensen Limited | F12: 46077 | H12: 46037 | I12: R | J12: Complete | K12: 40 | L12: 2858.6 | M12: =IF(OR($K12="",$L12=""),"",$L12/$K12) -> 71.465 | N12: 0.2 | O12: =IF($L12="","",$L12*IF($N12="",Settings!$J$11,$N12)) -> 571.72 | P12: =IF($L12="","",$L12+$O12) -> 3430.32 | Q12: Yes | S12: =IF($L12="","",IF($Q12<>"Yes",0,IF($R12<>"",$R12,ROUND($L12*Settings!$J$4,2)))) -> 285.86 | T12: =IF($L12="","",$P12+$S12) -> 3716.18 | U12: =IF($L12="","",ROUND($P12/2,2)+$S12) -> 2001.02 | V12: 1605.08 | W12: CC | X12: 46037 | Y12: 1806.89 | Z12: CC | AA12: 46069 | AE12: =IF($L12="","",SUM($V12,$Y12,$AB12)) -> 3411.97 | AF12: =IF(OR($L12="",$T12=0),"",IF(OR($J12="Complete",$J12="Paid in Full"),1,$AE12/$T12)) -> 1 | AG12: =IF($L12="","",IF(OR($J12="Cancelled",$J12="Complete",$J12="Paid in Full"),0,ROUND($T12-$AE12,2))) -> 0 | AH12: =IF(OR($L12="",$H12="",$AG12<=0),"",MAX(0,TODAY()-($H12+Settings!$J$6))) | AI12: 285.86 | AM12: CC | AN12: 46091 | AO12: =IF(OR($L12="",$S12=0,$AI12=""),0,ROUND($S12-$AI12,2)) -> 0 | AP12: =IF($L12="","",ROUND($L12+$AO12,2)) -> 2858.6 | AR12: =IF($L12="","",IF(ISNUMBER($F12),$F12,IF(ISNUMBER($G12),$G12,""))) -> 46077 | AS12: =IF(OR($L12="",$AR12=""),"",DATE(YEAR($AR12),MONTH($AR12),1)) -> 46054 | AT12: =IF($L12="","",IF($AR12<>"",YEAR($AR12),IF(ISNUMBER($H12),YEAR($H12),""))) -> 2026
A13: Danelle | B13: Penni Black | C13: C | D13: 22004208 | E13: SGN - Day 1 | F13: 46050 | H13: 46038 | I13: R | J13: Complete | K13: 27 | L13: 1381.9 | M13: =IF(OR($K13="",$L13=""),"",$L13/$K13) -> 51.181481 | N13: 0.2 | O13: =IF($L13="","",$L13*IF($N13="",Settings!$J$11,$N13)) -> 276.38 | P13: =IF($L13="","",$L13+$O13) -> 1658.28 | Q13: No | S13: =IF($L13="","",IF($Q13<>"Yes",0,IF($R13<>"",$R13,ROUND($L13*Settings!$J$4,2)))) -> 0 | T13: =IF($L13="","",$P13+$S13) -> 1658.28 | U13: =IF($L13="","",ROUND($P13/2,2)+$S13) -> 829.14 | V13: 1658.28 | W13: CC | X13: 46041 | AE13: =IF($L13="","",SUM($V13,$Y13,$AB13)) -> 1658.28 | AF13: =IF(OR($L13="",$T13=0),"",IF(OR($J13="Complete",$J13="Paid in Full"),1,$AE13/$T13)) -> 1 | AG13: =IF($L13="","",IF(OR($J13="Cancelled",$J13="Complete",$J13="Paid in Full"),0,ROUND($T13-$AE13,2))) -> 0 | AH13: =IF(OR($L13="",$H13="",$AG13<=0),"",MAX(0,TODAY()-($H13+Settings!$J$6))) | AO13: =IF(OR($L13="",$S13=0,$AI13=""),0,ROUND($S13-$AI13,2)) -> 0 | AP13: =IF($L13="","",ROUND($L13+$AO13,2)) -> 1381.9 | AR13: =IF($L13="","",IF(ISNUMBER($F13),$F13,IF(ISNUMBER($G13),$G13,""))) -> 46050 | AS13: =IF(OR($L13="",$AR13=""),"",DATE(YEAR($AR13),MONTH($AR13),1)) -> 46023 | AT13: =IF($L13="","",IF($AR13<>"",YEAR($AR13),IF(ISNUMBER($H13),YEAR($H13),""))) -> 2026
A14: Danelle | B14: Penni Black | C14: C | D14: 22004209 | E14: SGN - Day 2 | F14: 46051 | H14: 46038 | I14: R | J14: Complete | K14: 30 | L14: 1478.5 | M14: =IF(OR($K14="",$L14=""),"",$L14/$K14) -> 49.283333 | N14: 0.2 | O14: =IF($L14="","",$L14*IF($N14="",Settings!$J$11,$N14)) -> 295.7 | P14: =IF($L14="","",$L14+$O14) -> 1774.2 | Q14: No | S14: =IF($L14="","",IF($Q14<>"Yes",0,IF($R14<>"",$R14,ROUND($L14*Settings!$J$4,2)))) -> 0 | T14: =IF($L14="","",$P14+$S14) -> 1774.2 | U14: =IF($L14="","",ROUND($P14/2,2)+$S14) -> 887.1 | V14: 1774.2 | W14: CC | X14: 46041 | AE14: =IF($L14="","",SUM($V14,$Y14,$AB14)) -> 1774.2 | AF14: =IF(OR($L14="",$T14=0),"",IF(OR($J14="Complete",$J14="Paid in Full"),1,$AE14/$T14)) -> 1 | AG14: =IF($L14="","",IF(OR($J14="Cancelled",$J14="Complete",$J14="Paid in Full"),0,ROUND($T14-$AE14,2))) -> 0 | AH14: =IF(OR($L14="",$H14="",$AG14<=0),"",MAX(0,TODAY()-($H14+Settings!$J$6))) | AO14: =IF(OR($L14="",$S14=0,$AI14=""),0,ROUND($S14-$AI14,2)) -> 0 | AP14: =IF($L14="","",ROUND($L14+$AO14,2)) -> 1478.5 | AR14: =IF($L14="","",IF(ISNUMBER($F14),$F14,IF(ISNUMBER($G14),$G14,""))) -> 46051 | AS14: =IF(OR($L14="",$AR14=""),"",DATE(YEAR($AR14),MONTH($AR14),1)) -> 46023 | AT14: =IF($L14="","",IF($AR14<>"",YEAR($AR14),IF(ISNUMBER($H14),YEAR($H14),""))) -> 2026
A15: Charlotte | B15: Penni Black | E15: Delegation european union | F15: 46037 | H15: 46039 | I15: R | J15: Complete | K15: 87 | L15: 1827 | M15: =IF(OR($K15="",$L15=""),"",$L15/$K15) -> 21 | N15: 0.2 | O15: =IF($L15="","",$L15*IF($N15="",Settings!$J$11,$N15)) -> 365.4 | P15: =IF($L15="","",$L15+$O15) -> 2192.4 | Q15: No | S15: =IF($L15="","",IF($Q15<>"Yes",0,IF($R15<>"",$R15,ROUND($L15*Settings!$J$4,2)))) -> 0 | T15: =IF($L15="","",$P15+$S15) -> 2192.4 | U15: =IF($L15="","",ROUND($P15/2,2)+$S15) -> 1096.2 | V15: 2192.4 | W15: BACS | X15: 46084 | AE15: =IF($L15="","",SUM($V15,$Y15,$AB15)) -> 2192.4 | AF15: =IF(OR($L15="",$T15=0),"",IF(OR($J15="Complete",$J15="Paid in Full"),1,$AE15/$T15)) -> 1 | AG15: =IF($L15="","",IF(OR($J15="Cancelled",$J15="Complete",$J15="Paid in Full"),0,ROUND($T15-$AE15,2))) -> 0 | AH15: =IF(OR($L15="",$H15="",$AG15<=0),"",MAX(0,TODAY()-($H15+Settings!$J$6))) | AO15: =IF(OR($L15="",$S15=0,$AI15=""),0,ROUND($S15-$AI15,2)) -> 0 | AP15: =IF($L15="","",ROUND($L15+$AO15,2)) -> 1827 | AR15: =IF($L15="","",IF(ISNUMBER($F15),$F15,IF(ISNUMBER($G15),$G15,""))) -> 46037 | AS15: =IF(OR($L15="",$AR15=""),"",DATE(YEAR($AR15),MONTH($AR15),1)) -> 46023 | AT15: =IF($L15="","",IF($AR15<>"",YEAR($AR15),IF(ISNUMBER($H15),YEAR($H15),""))) -> 2026
A16: Danelle | B16: Penni Black | C16: C | D16: 22004210 | E16: Winston & Strawn | F16: 46043 | H16: 46040 | I16: R | J16: Complete | K16: 40 | L16: 1092 | M16: =IF(OR($K16="",$L16=""),"",$L16/$K16) -> 27.3 | N16: 0.2 | O16: =IF($L16="","",$L16*IF($N16="",Settings!$J$11,$N16)) -> 218.4 | P16: =IF($L16="","",$L16+$O16) -> 1310.4 | Q16: No | S16: =IF($L16="","",IF($Q16<>"Yes",0,IF($R16<>"",$R16,ROUND($L16*Settings!$J$4,2)))) -> 0 | T16: =IF($L16="","",$P16+$S16) -> 1310.4 | U16: =IF($L16="","",ROUND($P16/2,2)+$S16) -> 655.2 | V16: 1310.4 | W16: CC | X16: 46041 | AE16: =IF($L16="","",SUM($V16,$Y16,$AB16)) -> 1310.4 | AF16: =IF(OR($L16="",$T16=0),"",IF(OR($J16="Complete",$J16="Paid in Full"),1,$AE16/$T16)) -> 1 | AG16: =IF($L16="","",IF(OR($J16="Cancelled",$J16="Complete",$J16="Paid in Full"),0,ROUND($T16-$AE16,2))) -> 0 | AH16: =IF(OR($L16="",$H16="",$AG16<=0),"",MAX(0,TODAY()-($H16+Settings!$J$6))) | AO16: =IF(OR($L16="",$S16=0,$AI16=""),0,ROUND($S16-$AI16,2)) -> 0 | AP16: =IF($L16="","",ROUND($L16+$AO16,2)) -> 1092 | AR16: =IF($L16="","",IF(ISNUMBER($F16),$F16,IF(ISNUMBER($G16),$G16,""))) -> 46043 | AS16: =IF(OR($L16="",$AR16=""),"",DATE(YEAR($AR16),MONTH($AR16),1)) -> 46023 | AT16: =IF($L16="","",IF($AR16<>"",YEAR($AR16),IF(ISNUMBER($H16),YEAR($H16),""))) -> 2026
A17: Danelle | B17: Penni Black | C17: C | D17: 22004211 | E17: Humanists | F17: 46065 | H17: 46043 | I17: R | J17: Complete | K17: 70 | L17: 3908.43 | M17: =IF(OR($K17="",$L17=""),"",$L17/$K17) -> 55.834714 | N17: 0.2 | O17: =IF($L17="","",$L17*IF($N17="",Settings!$J$11,$N17)) -> 781.686 | P17: =IF($L17="","",$L17+$O17) -> 4690.116 | Q17: Yes | S17: =IF($L17="","",IF($Q17<>"Yes",0,IF($R17<>"",$R17,ROUND($L17*Settings!$J$4,2)))) -> 390.84 | T17: =IF($L17="","",$P17+$S17) -> 5080.956 | U17: =IF($L17="","",ROUND($P17/2,2)+$S17) -> 2735.9 | V17: 5080.96 | W17: BACS | X17: 46062 | AE17: =IF($L17="","",SUM($V17,$Y17,$AB17)) -> 5080.96 | AF17: =IF(OR($L17="",$T17=0),"",IF(OR($J17="Complete",$J17="Paid in Full"),1,$AE17/$T17)) -> 1 | AG17: =IF($L17="","",IF(OR($J17="Cancelled",$J17="Complete",$J17="Paid in Full"),0,ROUND($T17-$AE17,2))) -> 0 | AH17: =IF(OR($L17="",$H17="",$AG17<=0),"",MAX(0,TODAY()-($H17+Settings!$J$6))) | AI17: 390.84 | AJ17: British Humanist Assocation | AK17: 0-9 90 01 | AL17: 65005749 | AM17: BACS | AN17: 46089 | AO17: =IF(OR($L17="",$S17=0,$AI17=""),0,ROUND($S17-$AI17,2)) -> 0 | AP17: =IF($L17="","",ROUND($L17+$AO17,2)) -> 3908.43 | AR17: =IF($L17="","",IF(ISNUMBER($F17),$F17,IF(ISNUMBER($G17),$G17,""))) -> 46065 | AS17: =IF(OR($L17="",$AR17=""),"",DATE(YEAR($AR17),MONTH($AR17),1)) -> 46054 | AT17: =IF($L17="","",IF($AR17<>"",YEAR($AR17),IF(ISNUMBER($H17),YEAR($H17),""))) -> 2026
A18: Danelle | B18: Penni Black | C18: C | D18: 22004212 | E18: Humanists | F18: 46086 | H18: 46043 | I18: R | J18: Complete | K18: 70 | L18: 3908.43 | M18: =IF(OR($K18="",$L18=""),"",$L18/$K18) -> 55.834714 | N18: 0.2 | O18: =IF($L18="","",$L18*IF($N18="",Settings!$J$11,$N18)) -> 781.686 | P18: =IF($L18="","",$L18+$O18) -> 4690.116 | Q18: Yes | S18: =IF($L18="","",IF($Q18<>"Yes",0,IF($R18<>"",$R18,ROUND($L18*Settings!$J$4,2)))) -> 390.84 | T18: =IF($L18="","",$P18+$S18) -> 5080.956 | U18: =IF($L18="","",ROUND($P18/2,2)+$S18) -> 2735.9 | V18: 5080.96 | W18: BACS | X18: 46062 | AE18: =IF($L18="","",SUM($V18,$Y18,$AB18)) -> 5080.96 | AF18: =IF(OR($L18="",$T18=0),"",IF(OR($J18="Complete",$J18="Paid in Full"),1,$AE18/$T18)) -> 1 | AG18: =IF($L18="","",IF(OR($J18="Cancelled",$J18="Complete",$J18="Paid in Full"),0,ROUND($T18-$AE18,2))) -> 0 | AH18: =IF(OR($L18="",$H18="",$AG18<=0),"",MAX(0,TODAY()-($H18+Settings!$J$6))) | AI18: 390.84 | AJ18: British Humanist Assocation | AK18: 0-9 90 01 | AL18: 65005749 | AM18: BACS | AN18: 46092 | AO18: =IF(OR($L18="",$S18=0,$AI18=""),0,ROUND($S18-$AI18,2)) -> 0 | AP18: =IF($L18="","",ROUND($L18+$AO18,2)) -> 3908.43 | AR18: =IF($L18="","",IF(ISNUMBER($F18),$F18,IF(ISNUMBER($G18),$G18,""))) -> 46086 | AS18: =IF(OR($L18="",$AR18=""),"",DATE(YEAR($AR18),MONTH($AR18),1)) -> 46082 | AT18: =IF($L18="","",IF($AR18<>"",YEAR($AR18),IF(ISNUMBER($H18),YEAR($H18),""))) -> 2026
A19: Danelle | B19: Penni Black | C19: C | D19: 22004213 | E19: Arini - DAY 1 | F19: 46048 | H19: 46044 | I19: R | J19: Complete | K19: 35 | L19: 2397.65 | M19: =IF(OR($K19="",$L19=""),"",$L19/$K19) -> 68.504286 | N19: 0.2 | O19: =IF($L19="","",$L19*IF($N19="",Settings!$J$11,$N19)) -> 479.53 | P19: =IF($L19="","",$L19+$O19) -> 2877.18 | Q19: Yes | S19: =IF($L19="","",IF($Q19<>"Yes",0,IF($R19<>"",$R19,ROUND($L19*Settings!$J$4,2)))) -> 239.77 | T19: =IF($L19="","",$P19+$S19) -> 3116.95 | U19: =IF($L19="","",ROUND($P19/2,2)+$S19) -> 1678.36 | V19: 3116.95 | W19: CC | X19: 46044 | AE19: =IF($L19="","",SUM($V19,$Y19,$AB19)) -> 3116.95 | AF19: =IF(OR($L19="",$T19=0),"",IF(OR($J19="Complete",$J19="Paid in Full"),1,$AE19/$T19)) -> 1 | AG19: =IF($L19="","",IF(OR($J19="Cancelled",$J19="Complete",$J19="Paid in Full"),0,ROUND($T19-$AE19,2))) -> 0 | AH19: =IF(OR($L19="",$H19="",$AG19<=0),"",MAX(0,TODAY()-($H19+Settings!$J$6))) | AI19: 239.77 | AM19: CC | AN19: 46057 | AO19: =IF(OR($L19="",$S19=0,$AI19=""),0,ROUND($S19-$AI19,2)) -> 0 | AP19: =IF($L19="","",ROUND($L19+$AO19,2)) -> 2397.65 | AR19: =IF($L19="","",IF(ISNUMBER($F19),$F19,IF(ISNUMBER($G19),$G19,""))) -> 46048 | AS19: =IF(OR($L19="",$AR19=""),"",DATE(YEAR($AR19),MONTH($AR19),1)) -> 46023 | AT19: =IF($L19="","",IF($AR19<>"",YEAR($AR19),IF(ISNUMBER($H19),YEAR($H19),""))) -> 2026
A20: Danelle | B20: Penni Black | C20: C | D20: 22004214 | E20: Arini - DAY 2 | F20: 46051 | H20: 46044 | I20: R | J20: Complete | K20: 25 | L20: 2018.85 | M20: =IF(OR($K20="",$L20=""),"",$L20/$K20) -> 80.754 | N20: 0.2 | O20: =IF($L20="","",$L20*IF($N20="",Settings!$J$11,$N20)) -> 403.77 | P20: =IF($L20="","",$L20+$O20) -> 2422.62 | Q20: Yes | S20: =IF($L20="","",IF($Q20<>"Yes",0,IF($R20<>"",$R20,ROUND($L20*Settings!$J$4,2)))) -> 201.89 | T20: =IF($L20="","",$P20+$S20) -> 2624.51 | U20: =IF($L20="","",ROUND($P20/2,2)+$S20) -> 1413.2 | V20: 2624.52 | W20: CC | X20: 46044 | AE20: =IF($L20="","",SUM($V20,$Y20,$AB20)) -> 2624.52 | AF20: =IF(OR($L20="",$T20=0),"",IF(OR($J20="Complete",$J20="Paid in Full"),1,$AE20/$T20)) -> 1 | AG20: =IF($L20="","",IF(OR($J20="Cancelled",$J20="Complete",$J20="Paid in Full"),0,ROUND($T20-$AE20,2))) -> 0 | AH20: =IF(OR($L20="",$H20="",$AG20<=0),"",MAX(0,TODAY()-($H20+Settings!$J$6))) | AI20: 201.89 | AM20: CC | AO20: =IF(OR($L20="",$S20=0,$AI20=""),0,ROUND($S20-$AI20,2)) -> 0 | AP20: =IF($L20="","",ROUND($L20+$AO20,2)) -> 2018.85 | AR20: =IF($L20="","",IF(ISNUMBER($F20),$F20,IF(ISNUMBER($G20),$G20,""))) -> 46051 | AS20: =IF(OR($L20="",$AR20=""),"",DATE(YEAR($AR20),MONTH($AR20),1)) -> 46023 | AT20: =IF($L20="","",IF($AR20<>"",YEAR($AR20),IF(ISNUMBER($H20),YEAR($H20),""))) -> 2026
A21: Danelle | B21: Penni Black | C21: C | D21: 22004215 | E21: Dixon Wilson | F21: 46093 | H21: 46044 | I21: R | J21: Complete | K21: 40 | L21: 1853.5 | M21: =IF(OR($K21="",$L21=""),"",$L21/$K21) -> 46.3375 | N21: 0.2 | O21: =IF($L21="","",$L21*IF($N21="",Settings!$J$11,$N21)) -> 370.7 | P21: =IF($L21="","",$L21+$O21) -> 2224.2 | Q21: Yes | S21: =IF($L21="","",IF($Q21<>"Yes",0,IF($R21<>"",$R21,ROUND($L21*Settings!$J$4,2)))) -> 185.35 | T21: =IF($L21="","",$P21+$S21) -> 2409.55 | U21: =IF($L21="","",ROUND($P21/2,2)+$S21) -> 1297.45 | V21: 1112.1 | W21: BACS | X21: 46066 | Y21: 1297.45 | Z21: BACS | AA21: 46084 | AE21: =IF($L21="","",SUM($V21,$Y21,$AB21)) -> 2409.55 | AF21: =IF(OR($L21="",$T21=0),"",IF(OR($J21="Complete",$J21="Paid in Full"),1,$AE21/$T21)) -> 1 | AG21: =IF($L21="","",IF(OR($J21="Cancelled",$J21="Complete",$J21="Paid in Full"),0,ROUND($T21-$AE21,2))) -> 0 | AH21: =IF(OR($L21="",$H21="",$AG21<=0),"",MAX(0,TODAY()-($H21+Settings!$J$6))) | AI21: 185.35 | AJ21: Dixon Wilson | AK21: 15-99-00 | AL21: 19332130 | AM21: BACS | AN21: 46095 | AO21: =IF(OR($L21="",$S21=0,$AI21=""),0,ROUND($S21-$AI21,2)) -> 0 | AP21: =IF($L21="","",ROUND($L21+$AO21,2)) -> 1853.5 | AR21: =IF($L21="","",IF(ISNUMBER($F21),$F21,IF(ISNUMBER($G21),$G21,""))) -> 46093 | AS21: =IF(OR($L21="",$AR21=""),"",DATE(YEAR($AR21),MONTH($AR21),1)) -> 46082 | AT21: =IF($L21="","",IF($AR21<>"",YEAR($AR21),IF(ISNUMBER($H21),YEAR($H21),""))) -> 2026
A22: Danelle | B22: Penni Black | C22: C | D22: 22004216 | E22: Mewburn Ellis | F22: 46078 | H22: 46048 | I22: R | J22: Complete | K22: 40 | L22: 3466.6 | M22: =IF(OR($K22="",$L22=""),"",$L22/$K22) -> 86.665 | N22: 0.2 | O22: =IF($L22="","",$L22*IF($N22="",Settings!$J$11,$N22)) -> 693.32 | P22: =IF($L22="","",$L22+$O22) -> 4159.92 | Q22: Yes | S22: =IF($L22="","",IF($Q22<>"Yes",0,IF($R22<>"",$R22,ROUND($L22*Settings!$J$4,2)))) -> 346.66 | T22: =IF($L22="","",$P22+$S22) -> 4506.58 | U22: =IF($L22="","",ROUND($P22/2,2)+$S22) -> 2426.62 | V22: 4506.58 | W22: CC | X22: 46049 | AE22: =IF($L22="","",SUM($V22,$Y22,$AB22)) -> 4506.58 | AF22: =IF(OR($L22="",$T22=0),"",IF(OR($J22="Complete",$J22="Paid in Full"),1,$AE22/$T22)) -> 1 | AG22: =IF($L22="","",IF(OR($J22="Cancelled",$J22="Complete",$J22="Paid in Full"),0,ROUND($T22-$AE22,2))) -> 0 | AH22: =IF(OR($L22="",$H22="",$AG22<=0),"",MAX(0,TODAY()-($H22+Settings!$J$6))) | AI22: 346.66 | AM22: CC | AN22: 46057 | AO22: =IF(OR($L22="",$S22=0,$AI22=""),0,ROUND($S22-$AI22,2)) -> 0 | AP22: =IF($L22="","",ROUND($L22+$AO22,2)) -> 3466.6 | AR22: =IF($L22="","",IF(ISNUMBER($F22),$F22,IF(ISNUMBER($G22),$G22,""))) -> 46078 | AS22: =IF(OR($L22="",$AR22=""),"",DATE(YEAR($AR22),MONTH($AR22),1)) -> 46054 | AT22: =IF($L22="","",IF($AR22<>"",YEAR($AR22),IF(ISNUMBER($H22),YEAR($H22),""))) -> 2026
A23: Danelle | B23: Penni Black | C23: C | D23: 22004217 | E23: Perenco Holdings | F23: 46056 | H23: 46048 | I23: R | J23: Complete | K23: 120 | L23: 7161 | M23: =IF(OR($K23="",$L23=""),"",$L23/$K23) -> 59.675 | N23: 0.2 | O23: =IF($L23="","",$L23*IF($N23="",Settings!$J$11,$N23)) -> 1432.2 | P23: =IF($L23="","",$L23+$O23) -> 8593.2 | Q23: Yes | S23: =IF($L23="","",IF($Q23<>"Yes",0,IF($R23<>"",$R23,ROUND($L23*Settings!$J$4,2)))) -> 716.1 | T23: =IF($L23="","",$P23+$S23) -> 9309.3 | U23: =IF($L23="","",ROUND($P23/2,2)+$S23) -> 5012.7 | V23: 8593.2 | W23: BACS | X23: 46049 | Y23: 62.4 | Z23: CC | AA23: 46058 | AE23: =IF($L23="","",SUM($V23,$Y23,$AB23)) -> 8655.6 | AF23: =IF(OR($L23="",$T23=0),"",IF(OR($J23="Complete",$J23="Paid in Full"),1,$AE23/$T23)) -> 1 | AG23: =IF($L23="","",IF(OR($J23="Cancelled",$J23="Complete",$J23="Paid in Full"),0,ROUND($T23-$AE23,2))) -> 0 | AH23: =IF(OR($L23="",$H23="",$AG23<=0),"",MAX(0,TODAY()-($H23+Settings!$J$6))) | AI23: 716.1 | AO23: =IF(OR($L23="",$S23=0,$AI23=""),0,ROUND($S23-$AI23,2)) -> 0 | AP23: =IF($L23="","",ROUND($L23+$AO23,2)) -> 7161 | AR23: =IF($L23="","",IF(ISNUMBER($F23),$F23,IF(ISNUMBER($G23),$G23,""))) -> 46056 | AS23: =IF(OR($L23="",$AR23=""),"",DATE(YEAR($AR23),MONTH($AR23),1)) -> 46054 | AT23: =IF($L23="","",IF($AR23<>"",YEAR($AR23),IF(ISNUMBER($H23),YEAR($H23),""))) -> 2026
A24: Danelle | B24: Penni Black | C24: C | D24: 22004218 | E24: Emma Daniels | F24: 46061 | H24: 46055 | I24: R | J24: Complete | K24: 15 | L24: 2303.5 | M24: =IF(OR($K24="",$L24=""),"",$L24/$K24) -> 153.56667 | N24: 0.2 | O24: =IF($L24="","",$L24*IF($N24="",Settings!$J$11,$N24)) -> 460.7 | P24: =IF($L24="","",$L24+$O24) -> 2764.2 | Q24: Yes | S24: =IF($L24="","",IF($Q24<>"Yes",0,IF($R24<>"",$R24,ROUND($L24*Settings!$J$4,2)))) -> 230.35 | T24: =IF($L24="","",$P24+$S24) -> 2994.55 | U24: =IF($L24="","",ROUND($P24/2,2)+$S24) -> 1612.45 | AE24: =IF($L24="","",SUM($V24,$Y24,$AB24)) -> 0 | AF24: =IF(OR($L24="",$T24=0),"",IF(OR($J24="Complete",$J24="Paid in Full"),1,$AE24/$T24)) -> 1 | AG24: =IF($L24="","",IF(OR($J24="Cancelled",$J24="Complete",$J24="Paid in Full"),0,ROUND($T24-$AE24,2))) -> 0 | AH24: =IF(OR($L24="",$H24="",$AG24<=0),"",MAX(0,TODAY()-($H24+Settings!$J$6))) | AI24: 230.35 | AO24: =IF(OR($L24="",$S24=0,$AI24=""),0,ROUND($S24-$AI24,2)) -> 0 | AP24: =IF($L24="","",ROUND($L24+$AO24,2)) -> 2303.5 | AR24: =IF($L24="","",IF(ISNUMBER($F24),$F24,IF(ISNUMBER($G24),$G24,""))) -> 46061 | AS24: =IF(OR($L24="",$AR24=""),"",DATE(YEAR($AR24),MONTH($AR24),1)) -> 46054 | AT24: =IF($L24="","",IF($AR24<>"",YEAR($AR24),IF(ISNUMBER($H24),YEAR($H24),""))) -> 2026
A25: Danelle | B25: Penni Black | C25: W | D25: 22004219 | E25: Clara & Naren wedding tasting | F25: 46068 | H25: 46056 | I25: N | J25: Cancelled | K25: 2 | L25: 500 | M25: =IF(OR($K25="",$L25=""),"",$L25/$K25) -> 250 | N25: 0 | O25: =IF($L25="","",$L25*IF($N25="",Settings!$J$11,$N25)) -> 0 | P25: =IF($L25="","",$L25+$O25) -> 500 | Q25: No | S25: =IF($L25="","",IF($Q25<>"Yes",0,IF($R25<>"",$R25,ROUND($L25*Settings!$J$4,2)))) -> 0 | T25: =IF($L25="","",$P25+$S25) -> 500 | U25: =IF($L25="","",ROUND($P25/2,2)+$S25) -> 250 | AE25: =IF($L25="","",SUM($V25,$Y25,$AB25)) -> 0 | AF25: =IF(OR($L25="",$T25=0),"",IF(OR($J25="Complete",$J25="Paid in Full"),1,$AE25/$T25)) -> 0 | AG25: =IF($L25="","",IF(OR($J25="Cancelled",$J25="Complete",$J25="Paid in Full"),0,ROUND($T25-$AE25,2))) -> 0 | AH25: =IF(OR($L25="",$H25="",$AG25<=0),"",MAX(0,TODAY()-($H25+Settings!$J$6))) | AO25: =IF(OR($L25="",$S25=0,$AI25=""),0,ROUND($S25-$AI25,2)) -> 0 | AP25: =IF($L25="","",ROUND($L25+$AO25,2)) -> 500 | AR25: =IF($L25="","",IF(ISNUMBER($F25),$F25,IF(ISNUMBER($G25),$G25,""))) -> 46068 | AS25: =IF(OR($L25="",$AR25=""),"",DATE(YEAR($AR25),MONTH($AR25),1)) -> 46054 | AT25: =IF($L25="","",IF($AR25<>"",YEAR($AR25),IF(ISNUMBER($H25),YEAR($H25),""))) -> 2026
A26: Danelle | B26: Penni Black | C26: P | D26: 22004220 | E26: Alison Brown | F26: 46186 | H26: 46057 | I26: N | J26: Complete | K26: 60 | L26: 5096.5 | M26: =IF(OR($K26="",$L26=""),"",$L26/$K26) -> 84.941667 | N26: 0.2 | O26: =IF($L26="","",$L26*IF($N26="",Settings!$J$11,$N26)) -> 1019.3 | P26: =IF($L26="","",$L26+$O26) -> 6115.8 | Q26: Yes | S26: =IF($L26="","",IF($Q26<>"Yes",0,IF($R26<>"",$R26,ROUND($L26*Settings!$J$4,2)))) -> 509.65 | T26: =IF($L26="","",$P26+$S26) -> 6625.45 | U26: =IF($L26="","",ROUND($P26/2,2)+$S26) -> 3567.55 | V26: 3057.9 | W26: CC | X26: 46057 | Y26: 3168.25 | Z26: CC | AA26: 46175 | AE26: =IF($L26="","",SUM($V26,$Y26,$AB26)) -> 6226.15 | AF26: =IF(OR($L26="",$T26=0),"",IF(OR($J26="Complete",$J26="Paid in Full"),1,$AE26/$T26)) -> 1 | AG26: =IF($L26="","",IF(OR($J26="Cancelled",$J26="Complete",$J26="Paid in Full"),0,ROUND($T26-$AE26,2))) -> 0 | AH26: =IF(OR($L26="",$H26="",$AG26<=0),"",MAX(0,TODAY()-($H26+Settings!$J$6))) | AI26: 509.65 | AM26: CC | AN26: 46198 | AO26: =IF(OR($L26="",$S26=0,$AI26=""),0,ROUND($S26-$AI26,2)) -> 0 | AP26: =IF($L26="","",ROUND($L26+$AO26,2)) -> 5096.5 | AR26: =IF($L26="","",IF(ISNUMBER($F26),$F26,IF(ISNUMBER($G26),$G26,""))) -> 46186 | AS26: =IF(OR($L26="",$AR26=""),"",DATE(YEAR($AR26),MONTH($AR26),1)) -> 46174 | AT26: =IF($L26="","",IF($AR26<>"",YEAR($AR26),IF(ISNUMBER($H26),YEAR($H26),""))) -> 2026
A27: Danelle | B27: Penni Black | C27: C | D27: 22004221 | E27: George Jensen Limited | F27: 46065 | H27: 46058 | I27: R | J27: Complete | K27: 50 | L27: 1408.15 | M27: =IF(OR($K27="",$L27=""),"",$L27/$K27) -> 28.163 | N27: 0.2 | O27: =IF($L27="","",$L27*IF($N27="",Settings!$J$11,$N27)) -> 281.63 | P27: =IF($L27="","",$L27+$O27) -> 1689.78 | Q27: Yes | S27: =IF($L27="","",IF($Q27<>"Yes",0,IF($R27<>"",$R27,ROUND($L27*Settings!$J$4,2)))) -> 140.82 | T27: =IF($L27="","",$P27+$S27) -> 1830.6 | U27: =IF($L27="","",ROUND($P27/2,2)+$S27) -> 985.71 | V27: 1831.05 | W27: CC | X27: 46062 | AE27: =IF($L27="","",SUM($V27,$Y27,$AB27)) -> 1831.05 | AF27: =IF(OR($L27="",$T27=0),"",IF(OR($J27="Complete",$J27="Paid in Full"),1,$AE27/$T27)) -> 1 | AG27: =IF($L27="","",IF(OR($J27="Cancelled",$J27="Complete",$J27="Paid in Full"),0,ROUND($T27-$AE27,2))) -> 0 | AH27: =IF(OR($L27="",$H27="",$AG27<=0),"",MAX(0,TODAY()-($H27+Settings!$J$6))) | AI27: 140.82 | AM27: CC | AN27: 46068 | AO27: =IF(OR($L27="",$S27=0,$AI27=""),0,ROUND($S27-$AI27,2)) -> 0 | AP27: =IF($L27="","",ROUND($L27+$AO27,2)) -> 1408.15 | AR27: =IF($L27="","",IF(ISNUMBER($F27),$F27,IF(ISNUMBER($G27),$G27,""))) -> 46065 | AS27: =IF(OR($L27="",$AR27=""),"",DATE(YEAR($AR27),MONTH($AR27),1)) -> 46054 | AT27: =IF($L27="","",IF($AR27<>"",YEAR($AR27),IF(ISNUMBER($H27),YEAR($H27),""))) -> 2026
A28: Danelle | B28: Penni Black | C28: C | D28: 22004222 | E28: St Williams | F28: 46079 | H28: 46063 | I28: R | J28: Complete | K28: 40 | L28: 1956.4 | M28: =IF(OR($K28="",$L28=""),"",$L28/$K28) -> 48.91 | N28: 0.2 | O28: =IF($L28="","",$L28*IF($N28="",Settings!$J$11,$N28)) -> 391.28 | P28: =IF($L28="","",$L28+$O28) -> 2347.68 | Q28: Yes | S28: =IF($L28="","",IF($Q28<>"Yes",0,IF($R28<>"",$R28,ROUND($L28*Settings!$J$4,2)))) -> 195.64 | T28: =IF($L28="","",$P28+$S28) -> 2543.32 | U28: =IF($L28="","",ROUND($P28/2,2)+$S28) -> 1369.48 | V28: 2543.32 | W28: BACS | X28: 46071 | AE28: =IF($L28="","",SUM($V28,$Y28,$AB28)) -> 2543.32 | AF28: =IF(OR($L28="",$T28=0),"",IF(OR($J28="Complete",$J28="Paid in Full"),1,$AE28/$T28)) -> 1 | AG28: =IF($L28="","",IF(OR($J28="Cancelled",$J28="Complete",$J28="Paid in Full"),0,ROUND($T28-$AE28,2))) -> 0 | AH28: =IF(OR($L28="",$H28="",$AG28<=0),"",MAX(0,TODAY()-($H28+Settings!$J$6))) | AI28: 195.64 | AJ28: StWilliams Homes LLP - KRP | AK28: 20-92-96 | AL28: 205-81658 | AM28: BACS | AN28: 46089 | AO28: =IF(OR($L28="",$S28=0,$AI28=""),0,ROUND($S28-$AI28,2)) -> 0 | AP28: =IF($L28="","",ROUND($L28+$AO28,2)) -> 1956.4 | AR28: =IF($L28="","",IF(ISNUMBER($F28),$F28,IF(ISNUMBER($G28),$G28,""))) -> 46079 | AS28: =IF(OR($L28="",$AR28=""),"",DATE(YEAR($AR28),MONTH($AR28),1)) -> 46054 | AT28: =IF($L28="","",IF($AR28<>"",YEAR($AR28),IF(ISNUMBER($H28),YEAR($H28),""))) -> 2026
A29: Danelle | B29: Penni Black | C29: C | D29: 22004223 | E29: Arnold & Porter | F29: 46071 | H29: 46066 | I29: R | J29: Complete | K29: 70 | L29: 2017 | M29: =IF(OR($K29="",$L29=""),"",$L29/$K29) -> 28.814286 | N29: 0.2 | O29: =IF($L29="","",$L29*IF($N29="",Settings!$J$11,$N29)) -> 403.4 | P29: =IF($L29="","",$L29+$O29) -> 2420.4 | Q29: No | S29: =IF($L29="","",IF($Q29<>"Yes",0,IF($R29<>"",$R29,ROUND($L29*Settings!$J$4,2)))) -> 0 | T29: =IF($L29="","",$P29+$S29) -> 2420.4 | U29: =IF($L29="","",ROUND($P29/2,2)+$S29) -> 1210.2 | V29: 2420.4 | W29: BACS | AE29: =IF($L29="","",SUM($V29,$Y29,$AB29)) -> 2420.4 | AF29: =IF(OR($L29="",$T29=0),"",IF(OR($J29="Complete",$J29="Paid in Full"),1,$AE29/$T29)) -> 1 | AG29: =IF($L29="","",IF(OR($J29="Cancelled",$J29="Complete",$J29="Paid in Full"),0,ROUND($T29-$AE29,2))) -> 0 | AH29: =IF(OR($L29="",$H29="",$AG29<=0),"",MAX(0,TODAY()-($H29+Settings!$J$6))) | AO29: =IF(OR($L29="",$S29=0,$AI29=""),0,ROUND($S29-$AI29,2)) -> 0 | AP29: =IF($L29="","",ROUND($L29+$AO29,2)) -> 2017 | AR29: =IF($L29="","",IF(ISNUMBER($F29),$F29,IF(ISNUMBER($G29),$G29,""))) -> 46071 | AS29: =IF(OR($L29="",$AR29=""),"",DATE(YEAR($AR29),MONTH($AR29),1)) -> 46054 | AT29: =IF($L29="","",IF($AR29<>"",YEAR($AR29),IF(ISNUMBER($H29),YEAR($H29),""))) -> 2026
A30: Danelle | B30: Penni Black | C30: C | D30: 22004224 | E30: Colart International | F30: 46106 | H30: 46075 | I30: R | J30: Complete | K30: 50 | L30: 1377.3 | M30: =IF(OR($K30="",$L30=""),"",$L30/$K30) -> 27.546 | N30: 0.2 | O30: =IF($L30="","",$L30*IF($N30="",Settings!$J$11,$N30)) -> 275.46 | P30: =IF($L30="","",$L30+$O30) -> 1652.76 | Q30: No | S30: =IF($L30="","",IF($Q30<>"Yes",0,IF($R30<>"",$R30,ROUND($L30*Settings!$J$4,2)))) -> 0 | T30: =IF($L30="","",$P30+$S30) -> 1652.76 | U30: =IF($L30="","",ROUND($P30/2,2)+$S30) -> 826.38 | V30: 1652.76 | W30: BACS | X30: 46079 | AE30: =IF($L30="","",SUM($V30,$Y30,$AB30)) -> 1652.76 | AF30: =IF(OR($L30="",$T30=0),"",IF(OR($J30="Complete",$J30="Paid in Full"),1,$AE30/$T30)) -> 1 | AG30: =IF($L30="","",IF(OR($J30="Cancelled",$J30="Complete",$J30="Paid in Full"),0,ROUND($T30-$AE30,2))) -> 0 | AH30: =IF(OR($L30="",$H30="",$AG30<=0),"",MAX(0,TODAY()-($H30+Settings!$J$6))) | AO30: =IF(OR($L30="",$S30=0,$AI30=""),0,ROUND($S30-$AI30,2)) -> 0 | AP30: =IF($L30="","",ROUND($L30+$AO30,2)) -> 1377.3 | AR30: =IF($L30="","",IF(ISNUMBER($F30),$F30,IF(ISNUMBER($G30),$G30,""))) -> 46106 | AS30: =IF(OR($L30="",$AR30=""),"",DATE(YEAR($AR30),MONTH($AR30),1)) -> 46082 | AT30: =IF($L30="","",IF($AR30<>"",YEAR($AR30),IF(ISNUMBER($H30),YEAR($H30),""))) -> 2026
A31: Danelle | B31: Penni Black | C31: C | D31: 22004225 | E31: Zenith Bank Ltd - Day 1 & 2 | H31: 46075 | I31: R | J31: Complete | K31: 37 | L31: 4135.6 | M31: =IF(OR($K31="",$L31=""),"",$L31/$K31) -> 111.77297 | N31: 0.2 | O31: =IF($L31="","",$L31*IF($N31="",Settings!$J$11,$N31)) -> 827.12 | P31: =IF($L31="","",$L31+$O31) -> 4962.72 | Q31: Yes | S31: =IF($L31="","",IF($Q31<>"Yes",0,IF($R31<>"",$R31,ROUND($L31*Settings!$J$4,2)))) -> 413.56 | T31: =IF($L31="","",$P31+$S31) -> 5376.28 | U31: =IF($L31="","",ROUND($P31/2,2)+$S31) -> 2894.92 | V31: 5376.28 | W31: BACS | X31: 46080 | AE31: =IF($L31="","",SUM($V31,$Y31,$AB31)) -> 5376.28 | AF31: =IF(OR($L31="",$T31=0),"",IF(OR($J31="Complete",$J31="Paid in Full"),1,$AE31/$T31)) -> 1 | AG31: =IF($L31="","",IF(OR($J31="Cancelled",$J31="Complete",$J31="Paid in Full"),0,ROUND($T31-$AE31,2))) -> 0 | AH31: =IF(OR($L31="",$H31="",$AG31<=0),"",MAX(0,TODAY()-($H31+Settings!$J$6))) | AI31: 413.56 | AJ31: Zenith Bank UK Ltd | AK31: 40-02-50 | AL31: 81253972 | AM31: BACS | AN31: 46095 | AO31: =IF(OR($L31="",$S31=0,$AI31=""),0,ROUND($S31-$AI31,2)) -> 0 | AP31: =IF($L31="","",ROUND($L31+$AO31,2)) -> 4135.6 | AQ31: Event dates: 12 & 13th March. | AR31: =IF($L31="","",IF(ISNUMBER($F31),$F31,IF(ISNUMBER($G31),$G31,""))) | AS31: =IF(OR($L31="",$AR31=""),"",DATE(YEAR($AR31),MONTH($AR31),1)) | AT31: =IF($L31="","",IF($AR31<>"",YEAR($AR31),IF(ISNUMBER($H31),YEAR($H31),""))) -> 2026
A32: Danelle | B32: Penni Black | C32: C | D32: 22004226 | E32: Perenco Holdings | F32: 46093 | H32: 46075 | I32: R | J32: Complete | K32: 13 | L32: 847 | M32: =IF(OR($K32="",$L32=""),"",$L32/$K32) -> 65.153846 | N32: 0.2 | O32: =IF($L32="","",$L32*IF($N32="",Settings!$J$11,$N32)) -> 169.4 | P32: =IF($L32="","",$L32+$O32) -> 1016.4 | Q32: No | S32: =IF($L32="","",IF($Q32<>"Yes",0,IF($R32<>"",$R32,ROUND($L32*Settings!$J$4,2)))) -> 0 | T32: =IF($L32="","",$P32+$S32) -> 1016.4 | U32: =IF($L32="","",ROUND($P32/2,2)+$S32) -> 508.2 | AE32: =IF($L32="","",SUM($V32,$Y32,$AB32)) -> 0 | AF32: =IF(OR($L32="",$T32=0),"",IF(OR($J32="Complete",$J32="Paid in Full"),1,$AE32/$T32)) -> 1 | AG32: =IF($L32="","",IF(OR($J32="Cancelled",$J32="Complete",$J32="Paid in Full"),0,ROUND($T32-$AE32,2))) -> 0 | AH32: =IF(OR($L32="",$H32="",$AG32<=0),"",MAX(0,TODAY()-($H32+Settings!$J$6))) | AO32: =IF(OR($L32="",$S32=0,$AI32=""),0,ROUND($S32-$AI32,2)) -> 0 | AP32: =IF($L32="","",ROUND($L32+$AO32,2)) -> 847 | AR32: =IF($L32="","",IF(ISNUMBER($F32),$F32,IF(ISNUMBER($G32),$G32,""))) -> 46093 | AS32: =IF(OR($L32="",$AR32=""),"",DATE(YEAR($AR32),MONTH($AR32),1)) -> 46082 | AT32: =IF($L32="","",IF($AR32<>"",YEAR($AR32),IF(ISNUMBER($H32),YEAR($H32),""))) -> 2026
A33: Danelle | B33: Penni Black | C33: C | D33: 22004227 | E33: Cognizant | F33: 46085 | H33: 46077 | I33: R | J33: Complete | K33: 100 | L33: 7390.4 | M33: =IF(OR($K33="",$L33=""),"",$L33/$K33) -> 73.904 | N33: 0.2 | O33: =IF($L33="","",$L33*IF($N33="",Settings!$J$11,$N33)) -> 1478.08 | P33: =IF($L33="","",$L33+$O33) -> 8868.48 | Q33: Yes | S33: =IF($L33="","",IF($Q33<>"Yes",0,IF($R33<>"",$R33,ROUND($L33*Settings!$J$4,2)))) -> 739.04 | T33: =IF($L33="","",$P33+$S33) -> 9607.52 | U33: =IF($L33="","",ROUND($P33/2,2)+$S33) -> 5173.28 | V33: 6709.68 | W33: CC | X33: 46079 | Y33: 2897.84 | Z33: CC | AA33: 46079 | AE33: =IF($L33="","",SUM($V33,$Y33,$AB33)) -> 9607.52 | AF33: =IF(OR($L33="",$T33=0),"",IF(OR($J33="Complete",$J33="Paid in Full"),1,$AE33/$T33)) -> 1 | AG33: =IF($L33="","",IF(OR($J33="Cancelled",$J33="Complete",$J33="Paid in Full"),0,ROUND($T33-$AE33,2))) -> 0 | AH33: =IF(OR($L33="",$H33="",$AG33<=0),"",MAX(0,TODAY()-($H33+Settings!$J$6))) | AI33: 739.04 | AM33: CC | AN33: 46089 | AO33: =IF(OR($L33="",$S33=0,$AI33=""),0,ROUND($S33-$AI33,2)) -> 0 | AP33: =IF($L33="","",ROUND($L33+$AO33,2)) -> 7390.4 | AR33: =IF($L33="","",IF(ISNUMBER($F33),$F33,IF(ISNUMBER($G33),$G33,""))) -> 46085 | AS33: =IF(OR($L33="",$AR33=""),"",DATE(YEAR($AR33),MONTH($AR33),1)) -> 46082 | AT33: =IF($L33="","",IF($AR33<>"",YEAR($AR33),IF(ISNUMBER($H33),YEAR($H33),""))) -> 2026
A34: Danelle | B34: Penni Black | C34: C | D34: 22004228 | E34: House of Decant | F34: 46084 | H34: 46077 | I34: N | J34: Complete | K34: 25 | L34: 514 | M34: =IF(OR($K34="",$L34=""),"",$L34/$K34) -> 20.56 | N34: 0.2 | O34: =IF($L34="","",$L34*IF($N34="",Settings!$J$11,$N34)) -> 102.8 | P34: =IF($L34="","",$L34+$O34) -> 616.8 | Q34: No | S34: =IF($L34="","",IF($Q34<>"Yes",0,IF($R34<>"",$R34,ROUND($L34*Settings!$J$4,2)))) -> 0 | T34: =IF($L34="","",$P34+$S34) -> 616.8 | U34: =IF($L34="","",ROUND($P34/2,2)+$S34) -> 308.4 | AE34: =IF($L34="","",SUM($V34,$Y34,$AB34)) -> 0 | AF34: =IF(OR($L34="",$T34=0),"",IF(OR($J34="Complete",$J34="Paid in Full"),1,$AE34/$T34)) -> 1 | AG34: =IF($L34="","",IF(OR($J34="Cancelled",$J34="Complete",$J34="Paid in Full"),0,ROUND($T34-$AE34,2))) -> 0 | AH34: =IF(OR($L34="",$H34="",$AG34<=0),"",MAX(0,TODAY()-($H34+Settings!$J$6))) | AO34: =IF(OR($L34="",$S34=0,$AI34=""),0,ROUND($S34-$AI34,2)) -> 0 | AP34: =IF($L34="","",ROUND($L34+$AO34,2)) -> 514 | AR34: =IF($L34="","",IF(ISNUMBER($F34),$F34,IF(ISNUMBER($G34),$G34,""))) -> 46084 | AS34: =IF(OR($L34="",$AR34=""),"",DATE(YEAR($AR34),MONTH($AR34),1)) -> 46082 | AT34: =IF($L34="","",IF($AR34<>"",YEAR($AR34),IF(ISNUMBER($H34),YEAR($H34),""))) -> 2026
A35: Danelle | B35: Penni Black | C35: C | D35: 22004229 | E35: Conway Hall | F35: 46084 | H35: 46077 | I35: R | J35: Complete | K35: 60 | L35: 176 | M35: =IF(OR($K35="",$L35=""),"",$L35/$K35) -> 2.9333333 | N35: 0.2 | O35: =IF($L35="","",$L35*IF($N35="",Settings!$J$11,$N35)) -> 35.2 | P35: =IF($L35="","",$L35+$O35) -> 211.2 | Q35: No | S35: =IF($L35="","",IF($Q35<>"Yes",0,IF($R35<>"",$R35,ROUND($L35*Settings!$J$4,2)))) -> 0 | T35: =IF($L35="","",$P35+$S35) -> 211.2 | U35: =IF($L35="","",ROUND($P35/2,2)+$S35) -> 105.6 | V35: 211.2 | W35: CC | X35: 46080 | AE35: =IF($L35="","",SUM($V35,$Y35,$AB35)) -> 211.2 | AF35: =IF(OR($L35="",$T35=0),"",IF(OR($J35="Complete",$J35="Paid in Full"),1,$AE35/$T35)) -> 1 | AG35: =IF($L35="","",IF(OR($J35="Cancelled",$J35="Complete",$J35="Paid in Full"),0,ROUND($T35-$AE35,2))) -> 0 | AH35: =IF(OR($L35="",$H35="",$AG35<=0),"",MAX(0,TODAY()-($H35+Settings!$J$6))) | AO35: =IF(OR($L35="",$S35=0,$AI35=""),0,ROUND($S35-$AI35,2)) -> 0 | AP35: =IF($L35="","",ROUND($L35+$AO35,2)) -> 176 | AR35: =IF($L35="","",IF(ISNUMBER($F35),$F35,IF(ISNUMBER($G35),$G35,""))) -> 46084 | AS35: =IF(OR($L35="",$AR35=""),"",DATE(YEAR($AR35),MONTH($AR35),1)) -> 46082 | AT35: =IF($L35="","",IF($AR35<>"",YEAR($AR35),IF(ISNUMBER($H35),YEAR($H35),""))) -> 2026
A36: Danelle | B36: Penni Black | C36: C | D36: 22004230 | E36: Health Sciences University | F36: 46098 | H36: 46080 | I36: N | J36: Complete | K36: 100 | L36: 5061.25 | M36: =IF(OR($K36="",$L36=""),"",$L36/$K36) -> 50.6125 | N36: 0.2 | O36: =IF($L36="","",$L36*IF($N36="",Settings!$J$11,$N36)) -> 1012.25 | P36: =IF($L36="","",$L36+$O36) -> 6073.5 | Q36: Yes | S36: =IF($L36="","",IF($Q36<>"Yes",0,IF($R36<>"",$R36,ROUND($L36*Settings!$J$4,2)))) -> 506.13 | T36: =IF($L36="","",$P36+$S36) -> 6579.63 | U36: =IF($L36="","",ROUND($P36/2,2)+$S36) -> 3542.88 | V36: 6579.62 | W36: BACS | X36: 46089 | AE36: =IF($L36="","",SUM($V36,$Y36,$AB36)) -> 6579.62 | AF36: =IF(OR($L36="",$T36=0),"",IF(OR($J36="Complete",$J36="Paid in Full"),1,$AE36/$T36)) -> 1 | AG36: =IF($L36="","",IF(OR($J36="Cancelled",$J36="Complete",$J36="Paid in Full"),0,ROUND($T36-$AE36,2))) -> 0 | AH36: =IF(OR($L36="",$H36="",$AG36<=0),"",MAX(0,TODAY()-($H36+Settings!$J$6))) | AI36: 506.13 | AJ36: Health Sciences University | AK36: 51073796 | AL36: 40-46-19 | AM36: BACS | AN36: 46125 | AO36: =IF(OR($L36="",$S36=0,$AI36=""),0,ROUND($S36-$AI36,2)) -> 0 | AP36: =IF($L36="","",ROUND($L36+$AO36,2)) -> 5061.25 | AQ36: REF: “P/L PENN06 DEP RFND” | AR36: =IF($L36="","",IF(ISNUMBER($F36),$F36,IF(ISNUMBER($G36),$G36,""))) -> 46098 | AS36: =IF(OR($L36="",$AR36=""),"",DATE(YEAR($AR36),MONTH($AR36),1)) -> 46082 | AT36: =IF($L36="","",IF($AR36<>"",YEAR($AR36),IF(ISNUMBER($H36),YEAR($H36),""))) -> 2026
A37: Charlotte | B37: Penni Black | C37: C | D37: 22004231 | E37: Delegation european union | F37: 46079 | H37: 46079 | I37: R | J37: Complete | K37: 70 | L37: 1470 | M37: =IF(OR($K37="",$L37=""),"",$L37/$K37) -> 21 | N37: 0.2 | O37: =IF($L37="","",$L37*IF($N37="",Settings!$J$11,$N37)) -> 294 | P37: =IF($L37="","",$L37+$O37) -> 1764 | Q37: No | S37: =IF($L37="","",IF($Q37<>"Yes",0,IF($R37<>"",$R37,ROUND($L37*Settings!$J$4,2)))) -> 0 | T37: =IF($L37="","",$P37+$S37) -> 1764 | U37: =IF($L37="","",ROUND($P37/2,2)+$S37) -> 882 | V37: 1764 | W37: BACS | X37: 46125 | AE37: =IF($L37="","",SUM($V37,$Y37,$AB37)) -> 1764 | AF37: =IF(OR($L37="",$T37=0),"",IF(OR($J37="Complete",$J37="Paid in Full"),1,$AE37/$T37)) -> 1 | AG37: =IF($L37="","",IF(OR($J37="Cancelled",$J37="Complete",$J37="Paid in Full"),0,ROUND($T37-$AE37,2))) -> 0 | AH37: =IF(OR($L37="",$H37="",$AG37<=0),"",MAX(0,TODAY()-($H37+Settings!$J$6))) | AO37: =IF(OR($L37="",$S37=0,$AI37=""),0,ROUND($S37-$AI37,2)) -> 0 | AP37: =IF($L37="","",ROUND($L37+$AO37,2)) -> 1470 | AR37: =IF($L37="","",IF(ISNUMBER($F37),$F37,IF(ISNUMBER($G37),$G37,""))) -> 46079 | AS37: =IF(OR($L37="",$AR37=""),"",DATE(YEAR($AR37),MONTH($AR37),1)) -> 46054 | AT37: =IF($L37="","",IF($AR37<>"",YEAR($AR37),IF(ISNUMBER($H37),YEAR($H37),""))) -> 2026
A38: Danelle | B38: Penni Black | C38: C | D38: 22004232 | E38: MediaPlus UK | F38: 46086 | H38: 46082 | I38: N | J38: Complete | K38: 50 | L38: 910 | M38: =IF(OR($K38="",$L38=""),"",$L38/$K38) -> 18.2 | N38: 0.2 | O38: =IF($L38="","",$L38*IF($N38="",Settings!$J$11,$N38)) -> 182 | P38: =IF($L38="","",$L38+$O38) -> 1092 | Q38: No | S38: =IF($L38="","",IF($Q38<>"Yes",0,IF($R38<>"",$R38,ROUND($L38*Settings!$J$4,2)))) -> 0 | T38: =IF($L38="","",$P38+$S38) -> 1092 | U38: =IF($L38="","",ROUND($P38/2,2)+$S38) -> 546 | V38: 1092 | W38: BACS | X38: 46084 | AE38: =IF($L38="","",SUM($V38,$Y38,$AB38)) -> 1092 | AF38: =IF(OR($L38="",$T38=0),"",IF(OR($J38="Complete",$J38="Paid in Full"),1,$AE38/$T38)) -> 1 | AG38: =IF($L38="","",IF(OR($J38="Cancelled",$J38="Complete",$J38="Paid in Full"),0,ROUND($T38-$AE38,2))) -> 0 | AH38: =IF(OR($L38="",$H38="",$AG38<=0),"",MAX(0,TODAY()-($H38+Settings!$J$6))) | AO38: =IF(OR($L38="",$S38=0,$AI38=""),0,ROUND($S38-$AI38,2)) -> 0 | AP38: =IF($L38="","",ROUND($L38+$AO38,2)) -> 910 | AR38: =IF($L38="","",IF(ISNUMBER($F38),$F38,IF(ISNUMBER($G38),$G38,""))) -> 46086 | AS38: =IF(OR($L38="",$AR38=""),"",DATE(YEAR($AR38),MONTH($AR38),1)) -> 46082 | AT38: =IF($L38="","",IF($AR38<>"",YEAR($AR38),IF(ISNUMBER($H38),YEAR($H38),""))) -> 2026
A39: Charlotte | B39: Penni Black | C39: C | D39: 22004233 | E39: Steve Bosley Herne Hill | F39: 46081 | H39: 46083 | I39: R | J39: Complete | K39: 130 | L39: 1430 | M39: =IF(OR($K39="",$L39=""),"",$L39/$K39) -> 11 | N39: 0 | O39: =IF($L39="","",$L39*IF($N39="",Settings!$J$11,$N39)) -> 0 | P39: =IF($L39="","",$L39+$O39) -> 1430 | Q39: No | S39: =IF($L39="","",IF($Q39<>"Yes",0,IF($R39<>"",$R39,ROUND($L39*Settings!$J$4,2)))) -> 0 | T39: =IF($L39="","",$P39+$S39) -> 1430 | U39: =IF($L39="","",ROUND($P39/2,2)+$S39) -> 715 | AE39: =IF($L39="","",SUM($V39,$Y39,$AB39)) -> 0 | AF39: =IF(OR($L39="",$T39=0),"",IF(OR($J39="Complete",$J39="Paid in Full"),1,$AE39/$T39)) -> 1 | AG39: =IF($L39="","",IF(OR($J39="Cancelled",$J39="Complete",$J39="Paid in Full"),0,ROUND($T39-$AE39,2))) -> 0 | AH39: =IF(OR($L39="",$H39="",$AG39<=0),"",MAX(0,TODAY()-($H39+Settings!$J$6))) | AO39: =IF(OR($L39="",$S39=0,$AI39=""),0,ROUND($S39-$AI39,2)) -> 0 | AP39: =IF($L39="","",ROUND($L39+$AO39,2)) -> 1430 | AR39: =IF($L39="","",IF(ISNUMBER($F39),$F39,IF(ISNUMBER($G39),$G39,""))) -> 46081 | AS39: =IF(OR($L39="",$AR39=""),"",DATE(YEAR($AR39),MONTH($AR39),1)) -> 46054 | AT39: =IF($L39="","",IF($AR39<>"",YEAR($AR39),IF(ISNUMBER($H39),YEAR($H39),""))) -> 2026
A40: Danelle | B40: Penni Black | C40: C | D40: 22004234 | E40: SGN - Day 1 | F40: 46106 | H40: 46084 | I40: R | J40: Complete | K40: 30 | L40: 1465 | M40: =IF(OR($K40="",$L40=""),"",$L40/$K40) -> 48.833333 | N40: 0.2 | O40: =IF($L40="","",$L40*IF($N40="",Settings!$J$11,$N40)) -> 293 | P40: =IF($L40="","",$L40+$O40) -> 1758 | Q40: No | S40: =IF($L40="","",IF($Q40<>"Yes",0,IF($R40<>"",$R40,ROUND($L40*Settings!$J$4,2)))) -> 0 | T40: =IF($L40="","",$P40+$S40) -> 1758 | U40: =IF($L40="","",ROUND($P40/2,2)+$S40) -> 879 | V40: 1758 | W40: CC | X40: 46087 | AE40: =IF($L40="","",SUM($V40,$Y40,$AB40)) -> 1758 | AF40: =IF(OR($L40="",$T40=0),"",IF(OR($J40="Complete",$J40="Paid in Full"),1,$AE40/$T40)) -> 1 | AG40: =IF($L40="","",IF(OR($J40="Cancelled",$J40="Complete",$J40="Paid in Full"),0,ROUND($T40-$AE40,2))) -> 0 | AH40: =IF(OR($L40="",$H40="",$AG40<=0),"",MAX(0,TODAY()-($H40+Settings!$J$6))) | AO40: =IF(OR($L40="",$S40=0,$AI40=""),0,ROUND($S40-$AI40,2)) -> 0 | AP40: =IF($L40="","",ROUND($L40+$AO40,2)) -> 1465 | AR40: =IF($L40="","",IF(ISNUMBER($F40),$F40,IF(ISNUMBER($G40),$G40,""))) -> 46106 | AS40: =IF(OR($L40="",$AR40=""),"",DATE(YEAR($AR40),MONTH($AR40),1)) -> 46082 | AT40: =IF($L40="","",IF($AR40<>"",YEAR($AR40),IF(ISNUMBER($H40),YEAR($H40),""))) -> 2026
...

Sheet Collective
A1: PENNI BLACK COLLECTIVE | E1: {=IFERROR("NEXT PAYMENT: "&TEXT(INDEX($J$7:$J$18,MATCH(1,$N$7:$N$18,0)),"£#,##0.00")&" for "&TEXT(INDEX($A$7:$A$18,MATCH(1,$N$7:$N$18,0)),"MMMM")&" - in by "&TEXT(INDEX($L$7:$L$18,MATCH(1,$N$7:$N$18,0)),"D MMMM"),"ALL PAID UP TO DATE")} -> NEXT PAYMENT: £17,576.25 for September - in by 25 October
A2: =Settings!$J$8*100&"% of turnover, month by month, by EVENT date, running from "&TEXT(Settings!$J$10,"D MMMM YYYY")&". Turnover is ex VAT and adjusted by whatever the deposit refund actually came to. Cancelled jobs are excluded." -> 20% of turnover, month by month, by EVENT date, running from 1 September 2026. Turnover is ex VAT and adjusted by whatever the deposit refund actually came to. Cancelled jobs are excluded. | E2: {=IFERROR(IF(TODAY()>INDEX($L$7:$L$18,MATCH(1,$N$7:$N$18,0)),"OVERDUE - this should already be with the Collective",INDEX($L$7:$L$18,MATCH(1,$N$7:$N$18,0))-TODAY()&" days to go"),"")} -> 23 days to go
A3: Counting everything up to and including: | B3: =TODAY() -> 46297 | C3: Nothing with a later event date is counted.
A5: MONTH BY MONTH
A6: Month | B6: Jobs | C6: Turnover (ex VAT) | D6: Deposit taken | E6: Refund actually paid | F6: Deposit +/- | G6: NET TURNOVER (ex VAT) | H6: 20% DUE TO COLLECTIVE | I6: Paid to collective | J6: Outstanding | K6: Refunds still to do | L6: Pay by | M6: Payment status | N6: owing
A7: =DATE(Settings!$J$7,1,1) -> 46023 | B7: =COUNTIFS('Invoice Log'!$AS$3:$AS$303,$A7,'Invoice Log'!$AR$3:$AR$303,"<="&$B$3,'Invoice Log'!$AR$3:$AR$303,">="&Settings!$J$10,'Invoice Log'!$J$3:$J$303,"<>Cancelled") -> 0 | C7: =SUMIFS('Invoice Log'!$L$3:$L$303,'Invoice Log'!$AS$3:$AS$303,$A7,'Invoice Log'!$AR$3:$AR$303,"<="&$B$3,'Invoice Log'!$AR$3:$AR$303,">="&Settings!$J$10,'Invoice Log'!$J$3:$J$303,"<>Cancelled") -> 0 | D7: =SUMIFS('Invoice Log'!$S$3:$S$303,'Invoice Log'!$AS$3:$AS$303,$A7,'Invoice Log'!$AR$3:$AR$303,"<="&$B$3,'Invoice Log'!$AR$3:$AR$303,">="&Settings!$J$10,'Invoice Log'!$J$3:$J$303,"<>Cancelled") -> 0 | E7: =SUMIFS('Invoice Log'!$AI$3:$AI$303,'Invoice Log'!$AS$3:$AS$303,$A7,'Invoice Log'!$AR$3:$AR$303,"<="&$B$3,'Invoice Log'!$AR$3:$AR$303,">="&Settings!$J$10,'Invoice Log'!$J$3:$J$303,"<>Cancelled") -> 0 | F7: =SUMIFS('Invoice Log'!$AO$3:$AO$303,'Invoice Log'!$AS$3:$AS$303,$A7,'Invoice Log'!$AR$3:$AR$303,"<="&$B$3,'Invoice Log'!$AR$3:$AR$303,">="&Settings!$J$10,'Invoice Log'!$J$3:$J$303,"<>Cancelled") -> 0 | G7: =SUMIFS('Invoice Log'!$AP$3:$AP$303,'Invoice Log'!$AS$3:$AS$303,$A7,'Invoice Log'!$AR$3:$AR$303,"<="&$B$3,'Invoice Log'!$AR$3:$AR$303,">="&Settings!$J$10,'Invoice Log'!$J$3:$J$303,"<>Cancelled") -> 0 | H7: =ROUND($G7*Settings!$J$8,2) -> 0 | J7: =IF($H7=0,0,ROUND($H7-N($I7),2)) -> 0 | K7: =COUNTIFS('Invoice Log'!$AS$3:$AS$303,$A7,'Invoice Log'!$AR$3:$AR$303,"<="&$B$3,'Invoice Log'!$AR$3:$AR$303,">="&Settings!$J$10,'Invoice Log'!$J$3:$J$303,"<>Cancelled",'Invoice Log'!$S$3:$S$303,">0",'Invoice Log'!$AN$3:$AN$303,"") -> 0 | L7: =DATE(Settings!$J$7,2,Settings!$J$9) -> 46078 | M7: =IF(EOMONTH($A7,0)<Settings!$J$10,"before the Collective",IF($H7=0,"",IF(N($I7)>=$H7,"PAID",IF(TODAY()>$L7,"OVERDUE","Due "&TEXT($L7,"D MMM"))))) -> before the Collective | N7: =IF(AND($H7>0,N($I7)<$H7),1,0) -> 0
A8: =DATE(Settings!$J$7,2,1) -> 46054 | B8: =COUNTIFS('Invoice Log'!$AS$3:$AS$303,$A8,'Invoice Log'!$AR$3:$AR$303,"<="&$B$3,'Invoice Log'!$AR$3:$AR$303,">="&Settings!$J$10,'Invoice Log'!$J$3:$J$303,"<>Cancelled") -> 0 | C8: =SUMIFS('Invoice Log'!$L$3:$L$303,'Invoice Log'!$AS$3:$AS$303,$A8,'Invoice Log'!$AR$3:$AR$303,"<="&$B$3,'Invoice Log'!$AR$3:$AR$303,">="&Settings!$J$10,'Invoice Log'!$J$3:$J$303,"<>Cancelled") -> 0 | D8: =SUMIFS('Invoice Log'!$S$3:$S$303,'Invoice Log'!$AS$3:$AS$303,$A8,'Invoice Log'!$AR$3:$AR$303,"<="&$B$3,'Invoice Log'!$AR$3:$AR$303,">="&Settings!$J$10,'Invoice Log'!$J$3:$J$303,"<>Cancelled") -> 0 | E8: =SUMIFS('Invoice Log'!$AI$3:$AI$303,'Invoice Log'!$AS$3:$AS$303,$A8,'Invoice Log'!$AR$3:$AR$303,"<="&$B$3,'Invoice Log'!$AR$3:$AR$303,">="&Settings!$J$10,'Invoice Log'!$J$3:$J$303,"<>Cancelled") -> 0 | F8: =SUMIFS('Invoice Log'!$AO$3:$AO$303,'Invoice Log'!$AS$3:$AS$303,$A8,'Invoice Log'!$AR$3:$AR$303,"<="&$B$3,'Invoice Log'!$AR$3:$AR$303,">="&Settings!$J$10,'Invoice Log'!$J$3:$J$303,"<>Cancelled") -> 0 | G8: =SUMIFS('Invoice Log'!$AP$3:$AP$303,'Invoice Log'!$AS$3:$AS$303,$A8,'Invoice Log'!$AR$3:$AR$303,"<="&$B$3,'Invoice Log'!$AR$3:$AR$303,">="&Settings!$J$10,'Invoice Log'!$J$3:$J$303,"<>Cancelled") -> 0 | H8: =ROUND($G8*Settings!$J$8,2) -> 0 | J8: =IF($H8=0,0,ROUND($H8-N($I8),2)) -> 0 | K8: =COUNTIFS('Invoice Log'!$AS$3:$AS$303,$A8,'Invoice Log'!$AR$3:$AR$303,"<="&$B$3,'Invoice Log'!$AR$3:$AR$303,">="&Settings!$J$10,'Invoice Log'!$J$3:$J$303,"<>Cancelled",'Invoice Log'!$S$3:$S$303,">0",'Invoice Log'!$AN$3:$AN$303,"") -> 0 | L8: =DATE(Settings!$J$7,3,Settings!$J$9) -> 46106 | M8: =IF(EOMONTH($A8,0)<Settings!$J$10,"before the Collective",IF($H8=0,"",IF(N($I8)>=$H8,"PAID",IF(TODAY()>$L8,"OVERDUE","Due "&TEXT($L8,"D MMM"))))) -> before the Collective | N8: =IF(AND($H8>0,N($I8)<$H8),1,0) -> 0
A9: =DATE(Settings!$J$7,3,1) -> 46082 | B9: =COUNTIFS('Invoice Log'!$AS$3:$AS$303,$A9,'Invoice Log'!$AR$3:$AR$303,"<="&$B$3,'Invoice Log'!$AR$3:$AR$303,">="&Settings!$J$10,'Invoice Log'!$J$3:$J$303,"<>Cancelled") -> 0 | C9: =SUMIFS('Invoice Log'!$L$3:$L$303,'Invoice Log'!$AS$3:$AS$303,$A9,'Invoice Log'!$AR$3:$AR$303,"<="&$B$3,'Invoice Log'!$AR$3:$AR$303,">="&Settings!$J$10,'Invoice Log'!$J$3:$J$303,"<>Cancelled") -> 0 | D9: =SUMIFS('Invoice Log'!$S$3:$S$303,'Invoice Log'!$AS$3:$AS$303,$A9,'Invoice Log'!$AR$3:$AR$303,"<="&$B$3,'Invoice Log'!$AR$3:$AR$303,">="&Settings!$J$10,'Invoice Log'!$J$3:$J$303,"<>Cancelled") -> 0 | E9: =SUMIFS('Invoice Log'!$AI$3:$AI$303,'Invoice Log'!$AS$3:$AS$303,$A9,'Invoice Log'!$AR$3:$AR$303,"<="&$B$3,'Invoice Log'!$AR$3:$AR$303,">="&Settings!$J$10,'Invoice Log'!$J$3:$J$303,"<>Cancelled") -> 0 | F9: =SUMIFS('Invoice Log'!$AO$3:$AO$303,'Invoice Log'!$AS$3:$AS$303,$A9,'Invoice Log'!$AR$3:$AR$303,"<="&$B$3,'Invoice Log'!$AR$3:$AR$303,">="&Settings!$J$10,'Invoice Log'!$J$3:$J$303,"<>Cancelled") -> 0 | G9: =SUMIFS('Invoice Log'!$AP$3:$AP$303,'Invoice Log'!$AS$3:$AS$303,$A9,'Invoice Log'!$AR$3:$AR$303,"<="&$B$3,'Invoice Log'!$AR$3:$AR$303,">="&Settings!$J$10,'Invoice Log'!$J$3:$J$303,"<>Cancelled") -> 0 | H9: =ROUND($G9*Settings!$J$8,2) -> 0 | J9: =IF($H9=0,0,ROUND($H9-N($I9),2)) -> 0 | K9: =COUNTIFS('Invoice Log'!$AS$3:$AS$303,$A9,'Invoice Log'!$AR$3:$AR$303,"<="&$B$3,'Invoice Log'!$AR$3:$AR$303,">="&Settings!$J$10,'Invoice Log'!$J$3:$J$303,"<>Cancelled",'Invoice Log'!$S$3:$S$303,">0",'Invoice Log'!$AN$3:$AN$303,"") -> 0 | L9: =DATE(Settings!$J$7,4,Settings!$J$9) -> 46137 | M9: =IF(EOMONTH($A9,0)<Settings!$J$10,"before the Collective",IF($H9=0,"",IF(N($I9)>=$H9,"PAID",IF(TODAY()>$L9,"OVERDUE","Due "&TEXT($L9,"D MMM"))))) -> before the Collective | N9: =IF(AND($H9>0,N($I9)<$H9),1,0) -> 0
A10: =DATE(Settings!$J$7,4,1) -> 46113 | B10: =COUNTIFS('Invoice Log'!$AS$3:$AS$303,$A10,'Invoice Log'!$AR$3:$AR$303,"<="&$B$3,'Invoice Log'!$AR$3:$AR$303,">="&Settings!$J$10,'Invoice Log'!$J$3:$J$303,"<>Cancelled") -> 0 | C10: =SUMIFS('Invoice Log'!$L$3:$L$303,'Invoice Log'!$AS$3:$AS$303,$A10,'Invoice Log'!$AR$3:$AR$303,"<="&$B$3,'Invoice Log'!$AR$3:$AR$303,">="&Settings!$J$10,'Invoice Log'!$J$3:$J$303,"<>Cancelled") -> 0 | D10: =SUMIFS('Invoice Log'!$S$3:$S$303,'Invoice Log'!$AS$3:$AS$303,$A10,'Invoice Log'!$AR$3:$AR$303,"<="&$B$3,'Invoice Log'!$AR$3:$AR$303,">="&Settings!$J$10,'Invoice Log'!$J$3:$J$303,"<>Cancelled") -> 0 | E10: =SUMIFS('Invoice Log'!$AI$3:$AI$303,'Invoice Log'!$AS$3:$AS$303,$A10,'Invoice Log'!$AR$3:$AR$303,"<="&$B$3,'Invoice Log'!$AR$3:$AR$303,">="&Settings!$J$10,'Invoice Log'!$J$3:$J$303,"<>Cancelled") -> 0 | F10: =SUMIFS('Invoice Log'!$AO$3:$AO$303,'Invoice Log'!$AS$3:$AS$303,$A10,'Invoice Log'!$AR$3:$AR$303,"<="&$B$3,'Invoice Log'!$AR$3:$AR$303,">="&Settings!$J$10,'Invoice Log'!$J$3:$J$303,"<>Cancelled") -> 0 | G10: =SUMIFS('Invoice Log'!$AP$3:$AP$303,'Invoice Log'!$AS$3:$AS$303,$A10,'Invoice Log'!$AR$3:$AR$303,"<="&$B$3,'Invoice Log'!$AR$3:$AR$303,">="&Settings!$J$10,'Invoice Log'!$J$3:$J$303,"<>Cancelled") -> 0 | H10: =ROUND($G10*Settings!$J$8,2) -> 0 | J10: =IF($H10=0,0,ROUND($H10-N($I10),2)) -> 0 | K10: =COUNTIFS('Invoice Log'!$AS$3:$AS$303,$A10,'Invoice Log'!$AR$3:$AR$303,"<="&$B$3,'Invoice Log'!$AR$3:$AR$303,">="&Settings!$J$10,'Invoice Log'!$J$3:$J$303,"<>Cancelled",'Invoice Log'!$S$3:$S$303,">0",'Invoice Log'!$AN$3:$AN$303,"") -> 0 | L10: =DATE(Settings!$J$7,5,Settings!$J$9) -> 46167 | M10: =IF(EOMONTH($A10,0)<Settings!$J$10,"before the Collective",IF($H10=0,"",IF(N($I10)>=$H10,"PAID",IF(TODAY()>$L10,"OVERDUE","Due "&TEXT($L10,"D MMM"))))) -> before the Collective | N10: =IF(AND($H10>0,N($I10)<$H10),1,0) -> 0
